<?xml version="1.0" ?>

<robot name="nucobot">
  <!-- Base link -->
  <link name="base_link">
    <visual>
      <origin xyz="0 0 0" rpy="0 0 0" />
      <geometry>
          <box size="0.3 0.2 0.25"/>
      </geometry>
      <material name="yellow">
        <color rgba="0.8 0.8 0 1"/>
      </material>
    </visual>
  </link>
  <!-- Front Right Wheel -->
  <link name="f_r_wheel">
    <visual>
      <origin xyz="0 0 0" rpy="1.570795 0 0" />
      <geometry>
          <cylinder length="0.05" radius="0.05" />
      </geometry>
      <material name="black">
        <color rgba="0.05 0.05 0.05 1"/>
      </material>
    </visual>
  </link>
  <joint name="joint_f_r_wheel" type="continuous">
    <parent link="base_link"/>
    <child link="f_r_wheel"/>
    <origin xyz="0.15 -0.125 -0.125" rpy="0 0 0" /> 
    <axis xyz="0 1 0" rpy="0 0 0" />
  </joint>  
  <!-- Back Right Wheel -->
  <link name="b_r_wheel">
    <visual>
      <origin xyz="0 0 0" rpy="1.570795 0 0" />
      <geometry>
          <cylinder length="0.05" radius="0.05" />
      </geometry>
      <material name="black"/>
    </visual>
  </link>
  <joint name="joint_b_r_wheel" type="continuous">
    <parent link="base_link"/>
    <child link="b_r_wheel"/>
    <origin xyz="-0.15 -0.125 -0.125" rpy="0 0 0" /> 
    <axis xyz="0 1 0" rpy="0 0 0" />
  </joint>  
  <!-- Front Left Wheel -->
  <link name="f_l_wheel">
    <visual>
      <origin xyz="0 0 0" rpy="1.570795 0 0" />
      <geometry>
          <cylinder length="0.05" radius="0.05" />
      </geometry>
      <material name="black"/>
    </visual>
  </link>
  <joint name="joint_f_l_wheel" type="continuous">
    <parent link="base_link"/>
    <child link="f_l_wheel"/>
    <origin xyz="0.15 0.125 -0.125" rpy="0 0 0" /> 
    <axis xyz="0 1 0" rpy="0 0 0" />
  </joint>
  <!-- Back Left Wheel -->
  <link name="b_l_wheel">
    <visual>
      <origin xyz="0 0 0" rpy="1.570795 0 0" />
      <geometry>
          <cylinder length="0.05" radius="0.05" />
      </geometry>
      <material name="black"/>
    </visual>
  </link>
  <joint name="joint_b_l_wheel" type="continuous">
    <parent link="base_link"/>
    <child link="b_l_wheel"/>
    <origin xyz="-0.15 0.125 -0.125" rpy="0 0 0" /> 
    <axis xyz="0 1 0" rpy="0 0 0" />
  </joint>

  <gazebo>
    <plugin name="skid_steer_drive_controller" filename="libgazebo_ros_skid_steer_drive.so">
      <alwaysOn>true</alwaysOn>
      <updateRate>100.0</updateRate>
      <leftFrontJoint>front_left_wheel_joint</leftFrontJoint>
      <rightFrontJoint>front_right_wheel_joint</rightFrontJoint>
      <leftRearJoint>back_left_wheel_joint</leftRearJoint>
      <rightRearJoint>back_right_wheel_joint</rightRearJoint>
      <wheelSeparation>${base_y_size}</wheelSeparation>
      <wheelDiameter>${2*wheel_radius}</wheelDiameter>
      <torque>35</torque>
      <broadcastTF>1</broadcastTF>
      <odometryFrame>map</odometryFrame>
      <commandTopic>cmd_vel</commandTopic>
      <odometryTopic>odom</odometryTopic>
      <robotBaseFrame>base_footprint</robotBaseFrame>
    </plugin>
    <plugin name="gazebo_ros_control" filename="libgazebo_ros_control.so" />
  </gazebo>

      <!-- Transmission is important to link the joints and the controller -->
    <transmission name="${fb}_${lr}_wheel_joint_trans">
      <type>transmission_interface/SimpleTransmission</type>
      <joint name="${fb}_${lr}_wheel_joint">
        <hardwareInterface>EffortJointInterface</hardwareInterface>
      </joint>  
      <actuator name="${fb}_${lr}_wheel_joint_motor">
        <hardwareInterface>EffortJointInterface</hardwareInterface>
        <mechanicalReduction>1</mechanicalReduction>
      </actuator>
    </transmission>

    <gazebo>
      <plugin name="gazebo_ros_control" filename="libgazebo_ros_control.so">
        <robotNamespace>/nucobot</robotNamespace>
      </plugin>
    </gazebo>
</robot>