<?xml version="1.0"?>

<robot xmlns:xacro="http://ros.org/wiki/xacro">
  <xacro:property name="pi" value="3.1415926535897931" />

  <xacro:macro name="grip_finger" params="name parent *origin">
  <joint name="${name}_joint" type="continuous">
      <xacro:insert_block name="origin" />
      <parent link="${parent}"/>
      <child link="${name}_link"/>
      <axis xyz="0 0 1"/>
      <dynamics damping="0.7"/>
  </joint>
  <link name="${name}_link">
    <visual>
      <geometry>
        <mesh filename="package://nucobot_description/pikea/meshes/finger_visual.STL"
              scale="0.001 0.001 0.001"/>
      </geometry>
      <origin xyz="0.0 0.08 -0.007" rpy="${pi/2} 0 0"/>
    </visual>
    <collision>
      <geometry>
        <mesh filename="package://nucobot_description/pikea/meshes/finger_simple.STL"
              scale="0.001 0.001 0.001"/>
      </geometry>
      <origin xyz="0.0 0.08 -0.007" rpy="${pi/2} 0 0"/>
    </collision>
    <inertial>
      <origin xyz="0 0 0"/>
      <mass value="0.01"/>
      <inertia ixx="0.001" ixy="0.0" ixz="0.0"
               iyy="0.001" iyz="0.0" 
               izz="0.001" />
    </inertial>
  </link>
  <gazebo reference="${name}_link">
    <mu1>1.0</mu1>
    <mu2>1.0</mu2>
    <kp>1000000.0</kp>
    <kd>100.0</kd>
    <minDepth>0.001</minDepth>
    <maxVel>1.0</maxVel>
  </gazebo>
  <transmission name="${name}_transmission">
    <type>transmission_interface/SimpleTransmission</type>
    <joint name="${name}_joint"/>
    <actuator name="${name}_servo">
      <hardwareInterface>EffortJointInterface</hardwareInterface>
      <mechanicalReduction>1</mechanicalReduction>
    </actuator>
  </transmission>
  </xacro:macro>

  <xacro:macro name="gripper" params="name parent *origin">
  <!-- The gripper base -->
  <joint name="${name}_joint" type="fixed">
      <xacro:insert_block name="origin" />
      <parent link="${parent}"/>
      <child link="${name}_link"/>
  </joint>
  <link name="${name}_link">
    <visual>
      <geometry>
        <box size="0.01 0.01 0.01" />
      </geometry>
      <origin xyz="0 0 0" rpy="0 0 0"/>
    </visual>
    <collision>
      <geometry>
        <box size="0.01 0.01 0.01" />
      </geometry>
      <origin xyz="0 0 0" rpy="0 0 0"/>
    </collision>
    <inertial>
      <origin xyz="0 0 0"/>
      <mass value="0.1"/>
      <inertia ixx="0.1" ixy="0.0" ixz="0.0"
               iyy="0.1" iyz="0.0" 
               izz="0.1" />
    </inertial>
  </link>

  <!-- ... And two fingers -->
  <xacro:grip_finger name="${name}_rght_finger" parent="${name}_link">
     <origin xyz=" 0.003 0.0 0.0" rpy="0 0 0"/>
  </xacro:grip_finger>
  <xacro:grip_finger name="${name}_left_finger" parent="${name}_link">
     <origin xyz="-0.003 0.0 0.0" rpy="0 ${pi} 0"/>
  </xacro:grip_finger>
  </xacro:macro>
</robot>
